<robot name = "robot">
    <link name="Torso">
        <inertial>
            <origin xyz="0 0 1" rpy="0 0 0"/>
            <mass value="1" />
            <inertia ixx="100" ixy="0" ixz="0" iyy="100" iyz="0" izz="100" />
        </inertial>
        <visual>
            <origin xyz="0 0 1" rpy="0 0 0"/>
            <geometry>
                <box size="1 1 0.5" />
            </geometry>
            <material name="Cyan">
                <color rgba="0 1.0 1.0 1.0"/>
            </material>
        </visual>
        <collision>
            <origin xyz="0 0 1" rpy="0 0 0"/>
            <geometry>
                <box size="1 1 0.5" />
            </geometry>
        </collision>
    </link>
    <joint name="Torso_Leg_F" type="revolute">
       <parent link="Torso"/>
       <child  link="LegFront"/>
       <origin rpy="0 0 0" xyz="0 0.5 1"/>
       <axis xyz="1 0 0"/>
       <limit effort="0.0" lower="-3.14159" upper="3.14159" velocity="0.0"/>
    </joint>
    <link name="LegFront">
        <inertial>
            <origin xyz="0 0.5 0" rpy="0 0 0"/>
            <mass value="1" />
            <inertia ixx="100" ixy="0" ixz="0" iyy="100" iyz="0" izz="100" />
        </inertial>
        <visual>
            <origin xyz="0 0.5 0" rpy="0 0 0"/>
            <geometry>
                <box size="0.2 1 0.2" />
            </geometry>
            <material name="Cyan">
                <color rgba="0 1.0 1.0 1.0"/>
            </material>
        </visual>
        <collision>
            <origin xyz="0 0.5 0" rpy="0 0 0"/>
            <geometry>
                <box size="0.2 1 0.2" />
            </geometry>
        </collision>
    </link>
    <joint name="Leg_F_Leg_LF" type="revolute">
       <parent link="LegFront"/>
       <child  link="LegLowerFront"/>
       <origin rpy="0 0 0" xyz="0 1 0"/>
       <axis xyz="0 1 0"/>
       <limit effort="0.0" lower="-3.14159" upper="3.14159" velocity="0.0"/>
    </joint>
    <link name="LegLowerFront">
        <inertial>
            <origin xyz="0 0 -0.5" rpy="0 0 0"/>
            <mass value="1" />
            <inertia ixx="100" ixy="0" ixz="0" iyy="100" iyz="0" izz="100" />
        </inertial>
        <visual>
            <origin xyz="0 0 -0.5" rpy="0 0 0"/>
            <geometry>
                <box size="0.2 0.2 1" />
            </geometry>
            <material name="Cyan">
                <color rgba="0 1.0 1.0 1.0"/>
            </material>
        </visual>
        <collision>
            <origin xyz="0 0 -0.5" rpy="0 0 0"/>
            <geometry>
                <box size="0.2 0.2 1" />
            </geometry>
        </collision>
    </link>
    <joint name="Torso_Leg_B" type="revolute">
       <parent link="Torso"/>
       <child  link="LegBack"/>
       <origin rpy="0 0 0" xyz="0 -0.5 1"/>
       <axis xyz="1 0 0"/>
       <limit effort="0.0" lower="-3.14159" upper="3.14159" velocity="0.0"/>
    </joint>
    <link name="LegBack">
        <inertial>
            <origin xyz="0 -0.5 0" rpy="0 0 0"/>
            <mass value="1" />
            <inertia ixx="100" ixy="0" ixz="0" iyy="100" iyz="0" izz="100" />
        </inertial>
        <visual>
            <origin xyz="0 -0.5 0" rpy="0 0 0"/>
            <geometry>
                <box size="0.2 1 0.2" />
            </geometry>
            <material name="Cyan">
                <color rgba="0 1.0 1.0 1.0"/>
            </material>
        </visual>
        <collision>
            <origin xyz="0 -0.5 0" rpy="0 0 0"/>
            <geometry>
                <box size="0.2 1 0.2" />
            </geometry>
        </collision>
    </link>
    <joint name="Leg_B_Leg_LB" type="revolute">
       <parent link="LegBack"/>
       <child  link="LegLowerBack"/>
       <origin rpy="0 0 0" xyz="0 -1 0"/>
       <axis xyz="0 1 0"/>
       <limit effort="0.0" lower="-3.14159" upper="3.14159" velocity="0.0"/>
    </joint>
    <link name="LegLowerBack">
        <inertial>
            <origin xyz="0 0 -0.5" rpy="0 0 0"/>
            <mass value="1" />
            <inertia ixx="100" ixy="0" ixz="0" iyy="100" iyz="0" izz="100" />
        </inertial>
        <visual>
            <origin xyz="0 0 -0.5" rpy="0 0 0"/>
            <geometry>
                <box size="0.2 0.2 1" />
            </geometry>
            <material name="Cyan">
                <color rgba="0 1.0 1.0 1.0"/>
            </material>
        </visual>
        <collision>
            <origin xyz="0 0 -0.5" rpy="0 0 0"/>
            <geometry>
                <box size="0.2 0.2 1" />
            </geometry>
        </collision>
    </link>
    <joint name="Torso_Leg_R" type="revolute">
       <parent link="Torso"/>
       <child  link="LegRight"/>
       <origin rpy="0 0 0" xyz="0.5 0 1"/>
       <axis xyz="0 1 0"/>
       <limit effort="0.0" lower="-3.14159" upper="3.14159" velocity="0.0"/>
    </joint>
    <link name="LegRight">
        <inertial>
            <origin xyz="0.5 0 0" rpy="0 0 0"/>
            <mass value="1" />
            <inertia ixx="100" ixy="0" ixz="0" iyy="100" iyz="0" izz="100" />
        </inertial>
        <visual>
            <origin xyz="0.5 0 0" rpy="0 0 0"/>
            <geometry>
                <box size="1 0.2 0.2" />
            </geometry>
            <material name="Cyan">
                <color rgba="0 1.0 1.0 1.0"/>
            </material>
        </visual>
        <collision>
            <origin xyz="0.5 0 0" rpy="0 0 0"/>
            <geometry>
                <box size="1 0.2 0.2" />
            </geometry>
        </collision>
    </link>
    <joint name="Leg_R_Leg_LR" type="revolute">
       <parent link="LegRight"/>
       <child  link="LegLowerRight"/>
       <origin rpy="0 0 0" xyz="1 0 0"/>
       <axis xyz="1 0 0"/>
       <limit effort="0.0" lower="-3.14159" upper="3.14159" velocity="0.0"/>
    </joint>
    <link name="LegLowerRight">
        <inertial>
            <origin xyz="0 0 -0.5" rpy="0 0 0"/>
            <mass value="1" />
            <inertia ixx="100" ixy="0" ixz="0" iyy="100" iyz="0" izz="100" />
        </inertial>
        <visual>
            <origin xyz="0 0 -0.5" rpy="0 0 0"/>
            <geometry>
                <box size="0.2 0.2 1" />
            </geometry>
            <material name="Cyan">
                <color rgba="0 1.0 1.0 1.0"/>
            </material>
        </visual>
        <collision>
            <origin xyz="0 0 -0.5" rpy="0 0 0"/>
            <geometry>
                <box size="0.2 0.2 1" />
            </geometry>
        </collision>
    </link>
    <joint name="Torso_Leg_L" type="revolute">
       <parent link="Torso"/>
       <child  link="LegLeft"/>
       <origin rpy="0 0 0" xyz="-0.5 0 1"/>
       <axis xyz="0 1 0"/>
       <limit effort="0.0" lower="-3.14159" upper="3.14159" velocity="0.0"/>
    </joint>
    <link name="LegLeft">
        <inertial>
            <origin xyz="-0.5 0 0" rpy="0 0 0"/>
            <mass value="1" />
            <inertia ixx="100" ixy="0" ixz="0" iyy="100" iyz="0" izz="100" />
        </inertial>
        <visual>
            <origin xyz="-0.5 0 0" rpy="0 0 0"/>
            <geometry>
                <box size="1 0.2 0.2" />
            </geometry>
            <material name="Cyan">
                <color rgba="0 1.0 1.0 1.0"/>
            </material>
        </visual>
        <collision>
            <origin xyz="-0.5 0 0" rpy="0 0 0"/>
            <geometry>
                <box size="1 0.2 0.2" />
            </geometry>
        </collision>
    </link>
    <joint name="Leg_L_Leg_LL" type="revolute">
       <parent link="LegLeft"/>
       <child  link="LegLowerLeft"/>
       <origin rpy="0 0 0" xyz="-1 0 0"/>
       <axis xyz="1 0 0"/>
       <limit effort="0.0" lower="-3.14159" upper="3.14159" velocity="0.0"/>
    </joint>
    <link name="LegLowerLeft">
        <inertial>
            <origin xyz="0 0 -0.5" rpy="0 0 0"/>
            <mass value="1" />
            <inertia ixx="100" ixy="0" ixz="0" iyy="100" iyz="0" izz="100" />
        </inertial>
        <visual>
            <origin xyz="0 0 -0.5" rpy="0 0 0"/>
            <geometry>
                <box size="0.2 0.2 1" />
            </geometry>
            <material name="Cyan">
                <color rgba="0 1.0 1.0 1.0"/>
            </material>
        </visual>
        <collision>
            <origin xyz="0 0 -0.5" rpy="0 0 0"/>
            <geometry>
                <box size="0.2 0.2 1" />
            </geometry>
        </collision>
    </link>
</robot>